Workbook

Sheet Read Me
A1: KRONOS Eos — 5-Jahres-Finanzmodell (2026–2031)
A3: Zweck: Businessplan für eine Low-Cost-AME-Plattform (25–100 k€) auf Basis der KRONOS-Technologie.
A4: Struktur:
A5: • Annahmen — zentrale Parameter mit Evidenzstufen (A–D) und Quellenverweis
A6: • Konservativ / Base / Upside — vollständige P&L- und Cash-Modelle (editierbare Formeln)
A7: • Szenariovergleich — Kernkennzahlen und Diagramme
A8: • Sensitivität — Wirkung der wichtigsten Treiber auf EBITDA Jahr 5 und Kapitalbedarf (Base)
A9: • Returns — Exit-Szenarien und Investor-Rendite (inkl. Terminalperspektive Jahr 7)
A11: Konventionen: Alle Werte in k€ (real, ohne Indexierung). 2026 ist Vorlauf-/Entwicklungsjahr.
A12: Eingabezellen sind gelb hinterlegt — Änderungen fließen per Formel durch das gesamte Modell.
A14: Evidenzbasis: research/assumptions.md · research/sources.md · research/appendix/ (301 Findings)
A15: Regenerierung: python3 scripts/build_financial_model.py
... A17: Stand: 15.08.2026

Sheet Annahmen
A1: Zentrale Annahmen (Skalare) — Details je Jahr in den Szenario-Sheets
A3: Parameter | B3: Konservativ | C3: Base | D3: Upside | E3: Stufe | F3: Quelle / Herleitung
A4: Verbrauchsmaterial je Maschine/Jahr (k€) | B4: 3 | C4: 5 | D4: 8 | E4: C/D | F4: Tinten-/Pastenpreise (NovaCentrix u.a.); akademische Nutzung
A5: Bruttomarge Verbrauchsmaterial | B5: 0.55 | C5: 0.6 | D5: 0.65 | E5: C | F5: Comps Materialgeschäft 55–75 %
A6: Service-Attach-Rate (Bestand) | B6: 0.4 | C6: 0.5 | D6: 0.6 | E6: C | F6: Industriestandard Laborgeräte
A7: Servicepreis (% vom Listenpreis p.a.) | B7: 0.1 | C7: 0.11 | D7: 0.12 | E7: C | F7: Benchmark 10–15 % p.a.
A8: Bruttomarge Service | B8: 0.5 | C8: 0.5 | D8: 0.5 | E8: C | F8: Comps
A9: Software-Abo je Maschine (k€/Jahr) | B9: 1.2 | C9: 1.8 | D9: 2.4 | E9: C/D | F9: Benchmarks Eiger/Digital Factory
A10: Software-Attach-Rate | B10: 0.5 | C10: 0.6 | D10: 0.7 | E10: C/D
A11: Bruttomarge Software | B11: 0.85 | C11: 0.85 | D11: 0.85 | E11: C
A12: Kanalanteil ab 2028 | B12: 0.25 | C12: 0.25 | D12: 0.25 | E12: C | F12: APES/NTV-Kanal existiert; Beachhead primär direkt
A13: Distributorenrabatt | B13: 0.3 | C13: 0.3 | D13: 0.3 | E13: C | F13: Branche 20–35 %
A14: CAC je Direkteinheit (k€) | B14: 12 | C14: 9 | D14: 7 | E14: C | F14: 10–20 % vom ASP, messe-zentriert
A15: FTE-Vollkosten (k€/Jahr) | B15: 95 | C15: 95 | D15: 95 | E15: B | F15: Standort Nürnberg, Mischkalkulation
A16: Working Capital (% vom Umsatzzuwachs) | B16: 0.15 | C16: 0.12 | D16: 0.1 | E16: C | F16: Lager + Forderungen − Verbindlichkeiten
A17: Exit-Multiple (x Umsatz Jahr 5) | B17: 1 | C17: 2 | D17: 3 | E17: C | F17: Niche-HW-Comps: Markforged ~1,2x; Razor-Blade 2–4x
A18: Investorenanteil nach allen Tranchen | B18: 0.6 | C18: 0.55 | D18: 0.5 | E18: D | F18: Verhandlungsannahme, tranchiert
A19: Bruttomarge Applikationsservices | B19: 0.45 | C19: 0.45 | D19: 0.45 | E19: C | F19: PoC-Studien/NRE — Teil des heutigen KRONOS-Modells
A21: Hinweis: Jahresreihen (Stückzahlen, ASP, COGS-%, FTE, Opex, Grants, Capex) stehen als gelbe Eingabezeilen in den Szenario-Sheets.

Sheet Konservativ
A1: KRONOS Eos — Szenario Konservativ
A3: Position | B3: 2026 | C3: 2027 | D3: 2028 | E3: 2029 | F3: 2030 | G3: 2031 | H3: Notiz
A4: EINGABEN (gelb = editierbar)
A5: Verkaufte Einheiten | B5: 0 | C5: 8 | D5: 20 | E5: 35 | F5: 50 | G5: 65 | H5: D — Validierungsziel V1/V2
A6: Applikationsprojekte/NRE (Umsatz) | B6: 0 | C6: 200 | D6: 300 | E6: 400 | F6: 450 | G6: 500 | H6: PoC-Studien, Prozessintegration — heutiges KRONOS-Geschäft
A7: Listenpreis blended (k€) | B7: 0 | C7: 55 | D7: 57 | E7: 58 | F7: 59 | G7: 60 | H7: Mix Eos One/Five/Max ≈ 25/55/20 %; 2027 = Pilotpreise
A8: Maschinen-COGS (% v. Liste) | B8: 0 | C8: 0.6 | D8: 0.58 | E8: 0.56 | F8: 0.54 | G8: 0.52 | H8: C — BOM-These, Gate V3
A9: FTE | B9: 7 | C9: 10 | D9: 12 | E9: 14 | F9: 15 | G9: 16
A10: Entwicklung (Sachkosten) | B10: 500 | C10: 550 | D10: 350 | E10: 250 | F10: 200 | G10: 200 | H10: Plattform-Derivat aus Helios-Technik
A11: Zertifizierung (CE/UL) | B11: 0 | C11: 150 | D11: 0 | E11: 0 | F11: 0 | G11: 0
A12: Marketing & Messen | B12: 80 | C12: 300 | D12: 400 | E12: 450 | F12: 450 | G12: 450 | H12: LOPEC, productronica, electronica, Formnext
A13: G&A (Sachkosten) | B13: 120 | C13: 250 | D13: 300 | E13: 330 | F13: 350 | G13: 350
A14: Fördermittel (Zufluss) | B14: 250 | C14: 0 | D14: 0 | E14: 0 | F14: 0 | G14: 0 | H14: ZIM/Bayern; Upside inkl. EIC 2,5 M€
A15: Capex (inkl. Tooling, Demoflotte) | B15: 200 | C15: 500 | D15: 350 | E15: 300 | F15: 300 | G15: 300
A17: INSTALLIERTE BASIS
A18: Kumulierte Basis (Jahresende) | B18: =B5 | C18: =B18+C5 | D18: =C18+D5 | E18: =D18+E5 | F18: =E18+F5 | G18: =F18+G5
A19: Ø aktive Basis (Jahresmittel) | B19: =(0+B18)/2 | C19: =(B18+C18)/2 | D19: =(C18+D18)/2 | E19: =(D18+E18)/2 | F19: =(E18+F18)/2 | G19: =(F18+G18)/2
A20: Servicefähige Basis (Vorjahresbestand) | B20: =0 | C20: =B18 | D20: =C18 | E20: =D18 | F20: =E18 | G20: =F18
A22: UMSATZ
A23: Maschinenumsatz | B23: =B5*B7 | C23: =C5*C7 | D23: =D5*D7*(1-Annahmen!$B$12*Annahmen!$B$13) | E23: =E5*E7*(1-Annahmen!$B$12*Annahmen!$B$13) | F23: =F5*F7*(1-Annahmen!$B$12*Annahmen!$B$13) | G23: =G5*G7*(1-Annahmen!$B$12*Annahmen!$B$13) | H23: ab 2028 Kanalmix mit Distributorenrabatt
A24: Verbrauchsmaterial | B24: =B19*Annahmen!$B$4 | C24: =C19*Annahmen!$B$4 | D24: =D19*Annahmen!$B$4 | E24: =E19*Annahmen!$B$4 | F24: =F19*Annahmen!$B$4 | G24: =G19*Annahmen!$B$4
A25: Service & Wartung | B25: =B20*Annahmen!$B$6*Annahmen!$B$7*B7 | C25: =C20*Annahmen!$B$6*Annahmen!$B$7*C7 | D25: =D20*Annahmen!$B$6*Annahmen!$B$7*D7 | E25: =E20*Annahmen!$B$6*Annahmen!$B$7*E7 | F25: =F20*Annahmen!$B$6*Annahmen!$B$7*F7 | G25: =G20*Annahmen!$B$6*Annahmen!$B$7*G7
A26: Software (Aion-5X Abo) | B26: =B19*Annahmen!$B$10*Annahmen!$B$9 | C26: =C19*Annahmen!$B$10*Annahmen!$B$9 | D26: =D19*Annahmen!$B$10*Annahmen!$B$9 | E26: =E19*Annahmen!$B$10*Annahmen!$B$9 | F26: =F19*Annahmen!$B$10*Annahmen!$B$9 | G26: =G19*Annahmen!$B$10*Annahmen!$B$9
A27: Applikationsprojekte/NRE | B27: =B6 | C27: =C6 | D27: =D6 | E27: =E6 | F27: =F6 | G27: =G6
A28: Gesamtumsatz | B28: =SUM(B23:B27) | C28: =SUM(C23:C27) | D28: =SUM(D23:D27) | E28: =SUM(E23:E27) | F28: =SUM(F23:F27) | G28: =SUM(G23:G27)
A30: BRUTTOERGEBNIS
A31: COGS Maschinen | B31: =B5*B7*B8 | C31: =C5*C7*C8 | D31: =D5*D7*D8 | E31: =E5*E7*E8 | F31: =F5*F7*F8 | G31: =G5*G7*G8
A32: Bruttoergebnis | B32: =B23-B31+B24*Annahmen!$B$5+B25*Annahmen!$B$8+B26*Annahmen!$B$11+B27*Annahmen!$B$19 | C32: =C23-C31+C24*Annahmen!$B$5+C25*Annahmen!$B$8+C26*Annahmen!$B$11+C27*Annahmen!$B$19 | D32: =D23-D31+D24*Annahmen!$B$5+D25*Annahmen!$B$8+D26*Annahmen!$B$11+D27*Annahmen!$B$19 | E32: =E23-E31+E24*Annahmen!$B$5+E25*Annahmen!$B$8+E26*Annahmen!$B$11+E27*Annahmen!$B$19 | F32: =F23-F31+F24*Annahmen!$B$5+F25*Annahmen!$B$8+F26*Annahmen!$B$11+F27*Annahmen!$B$19 | G32: =G23-G31+G24*Annahmen!$B$5+G25*Annahmen!$B$8+G26*Annahmen!$B$11+G27*Annahmen!$B$19
A33: Bruttomarge % | B33: =IF(B28=0,0,B32/B28) | C33: =IF(C28=0,0,C32/C28) | D33: =IF(D28=0,0,D32/D28) | E33: =IF(E28=0,0,E32/E28) | F33: =IF(F28=0,0,F32/F28) | G33: =IF(G28=0,0,G32/G28)
A35: OPERATIVE KOSTEN
A36: Personal | B36: =B9*Annahmen!$B$15 | C36: =C9*Annahmen!$B$15 | D36: =D9*Annahmen!$B$15 | E36: =E9*Annahmen!$B$15 | F36: =F9*Annahmen!$B$15 | G36: =G9*Annahmen!$B$15
A37: Variabler Vertrieb (CAC direkt) | B37: =B5*Annahmen!$B$14 | C37: =C5*Annahmen!$B$14 | D37: =D5*(1-Annahmen!$B$12)*Annahmen!$B$14 | E37: =E5*(1-Annahmen!$B$12)*Annahmen!$B$14 | F37: =F5*(1-Annahmen!$B$12)*Annahmen!$B$14 | G37: =G5*(1-Annahmen!$B$12)*Annahmen!$B$14
A38: Opex gesamt | B38: =B36+B37+B10+B11+B12+B13 | C38: =C36+C37+C10+C11+C12+C13 | D38: =D36+D37+D10+D11+D12+D13 | E38: =E36+E37+E10+E11+E12+E13 | F38: =F36+F37+F10+F11+F12+F13 | G38: =G36+G37+G10+G11+G12+G13
A40: ERGEBNIS & LIQUIDITÄT
A41: EBITDA (inkl. Fördermittel) | B41: =B32-B38+B14 | C41: =C32-C38+C14 | D41: =D32-D38+D14 | E41: =E32-E38+E14 | F41: =F32-F38+F14 | G41: =G32-G38+G14
A42: EBITDA-Marge % | B42: =IF(B28=0,0,B41/B28) | C42: =IF(C28=0,0,C41/C28) | D42: =IF(D28=0,0,D41/D28) | E42: =IF(E28=0,0,E41/E28) | F42: =IF(F28=0,0,F41/F28) | G42: =IF(G28=0,0,G41/G28)
A43: Δ Working Capital | B43: =MAX(0,(B28-0)*Annahmen!$B$16) | C43: =MAX(0,(C28-B28)*Annahmen!$B$16) | D43: =MAX(0,(D28-C28)*Annahmen!$B$16) | E43: =MAX(0,(E28-D28)*Annahmen!$B$16) | F43: =MAX(0,(F28-E28)*Annahmen!$B$16) | G43: =MAX(0,(G28-F28)*Annahmen!$B$16)
A44: Free Cash Flow | B44: =B41-B15-B43 | C44: =C41-C15-C43 | D44: =D41-D15-D43 | E44: =E41-E15-E43 | F44: =F41-F15-F43 | G44: =G41-G15-G43
A45: Kumulierter Cash Flow | B45: =B44 | C45: =B45+C44 | D45: =C45+D44 | E45: =D45+E44 | F45: =E45+F44 | G45: =F45+G44
A47: KENNZAHLEN
...

Sheet Base
A1: KRONOS Eos — Szenario Base
A3: Position | B3: 2026 | C3: 2027 | D3: 2028 | E3: 2029 | F3: 2030 | G3: 2031 | H3: Notiz
A4: EINGABEN (gelb = editierbar)
A5: Verkaufte Einheiten | B5: 0 | C5: 12 | D5: 35 | E5: 75 | F5: 130 | G5: 200 | H5: D — Validierungsziel V1/V2
A6: Applikationsprojekte/NRE (Umsatz) | B6: 0 | C6: 300 | D6: 500 | E6: 800 | F6: 1000 | G6: 1200 | H6: PoC-Studien, Prozessintegration — heutiges KRONOS-Geschäft
A7: Listenpreis blended (k€) | B7: 0 | C7: 52 | D7: 60 | E7: 62 | F7: 63 | G7: 63.5 | H7: Mix Eos One/Five/Max ≈ 25/55/20 %; 2027 = Pilotpreise
A8: Maschinen-COGS (% v. Liste) | B8: 0 | C8: 0.58 | D8: 0.55 | E8: 0.52 | F8: 0.5 | G8: 0.48 | H8: C — BOM-These, Gate V3
A9: FTE | B9: 8 | C9: 13 | D9: 19 | E9: 26 | F9: 32 | G9: 38
A10: Entwicklung (Sachkosten) | B10: 500 | C10: 600 | D10: 400 | E10: 300 | F10: 300 | G10: 300 | H10: Plattform-Derivat aus Helios-Technik
A11: Zertifizierung (CE/UL) | B11: 0 | C11: 150 | D11: 0 | E11: 0 | F11: 0 | G11: 0
A12: Marketing & Messen | B12: 100 | C12: 350 | D12: 500 | E12: 700 | F12: 900 | G12: 1000 | H12: LOPEC, productronica, electronica, Formnext
A13: G&A (Sachkosten) | B13: 150 | C13: 300 | D13: 400 | E13: 500 | F13: 600 | G13: 700
A14: Fördermittel (Zufluss) | B14: 250 | C14: 300 | D14: 250 | E14: 0 | F14: 0 | G14: 0 | H14: ZIM/Bayern; Upside inkl. EIC 2,5 M€
A15: Capex (inkl. Tooling, Demoflotte) | B15: 200 | C15: 550 | D15: 450 | E15: 450 | F15: 500 | G15: 550
A17: INSTALLIERTE BASIS
A18: Kumulierte Basis (Jahresende) | B18: =B5 | C18: =B18+C5 | D18: =C18+D5 | E18: =D18+E5 | F18: =E18+F5 | G18: =F18+G5
A19: Ø aktive Basis (Jahresmittel) | B19: =(0+B18)/2 | C19: =(B18+C18)/2 | D19: =(C18+D18)/2 | E19: =(D18+E18)/2 | F19: =(E18+F18)/2 | G19: =(F18+G18)/2
A20: Servicefähige Basis (Vorjahresbestand) | B20: =0 | C20: =B18 | D20: =C18 | E20: =D18 | F20: =E18 | G20: =F18
A22: UMSATZ
A23: Maschinenumsatz | B23: =B5*B7 | C23: =C5*C7 | D23: =D5*D7*(1-Annahmen!$C$12*Annahmen!$C$13) | E23: =E5*E7*(1-Annahmen!$C$12*Annahmen!$C$13) | F23: =F5*F7*(1-Annahmen!$C$12*Annahmen!$C$13) | G23: =G5*G7*(1-Annahmen!$C$12*Annahmen!$C$13) | H23: ab 2028 Kanalmix mit Distributorenrabatt
A24: Verbrauchsmaterial | B24: =B19*Annahmen!$C$4 | C24: =C19*Annahmen!$C$4 | D24: =D19*Annahmen!$C$4 | E24: =E19*Annahmen!$C$4 | F24: =F19*Annahmen!$C$4 | G24: =G19*Annahmen!$C$4
A25: Service & Wartung | B25: =B20*Annahmen!$C$6*Annahmen!$C$7*B7 | C25: =C20*Annahmen!$C$6*Annahmen!$C$7*C7 | D25: =D20*Annahmen!$C$6*Annahmen!$C$7*D7 | E25: =E20*Annahmen!$C$6*Annahmen!$C$7*E7 | F25: =F20*Annahmen!$C$6*Annahmen!$C$7*F7 | G25: =G20*Annahmen!$C$6*Annahmen!$C$7*G7
A26: Software (Aion-5X Abo) | B26: =B19*Annahmen!$C$10*Annahmen!$C$9 | C26: =C19*Annahmen!$C$10*Annahmen!$C$9 | D26: =D19*Annahmen!$C$10*Annahmen!$C$9 | E26: =E19*Annahmen!$C$10*Annahmen!$C$9 | F26: =F19*Annahmen!$C$10*Annahmen!$C$9 | G26: =G19*Annahmen!$C$10*Annahmen!$C$9
A27: Applikationsprojekte/NRE | B27: =B6 | C27: =C6 | D27: =D6 | E27: =E6 | F27: =F6 | G27: =G6
A28: Gesamtumsatz | B28: =SUM(B23:B27) | C28: =SUM(C23:C27) | D28: =SUM(D23:D27) | E28: =SUM(E23:E27) | F28: =SUM(F23:F27) | G28: =SUM(G23:G27)
A30: BRUTTOERGEBNIS
A31: COGS Maschinen | B31: =B5*B7*B8 | C31: =C5*C7*C8 | D31: =D5*D7*D8 | E31: =E5*E7*E8 | F31: =F5*F7*F8 | G31: =G5*G7*G8
A32: Bruttoergebnis | B32: =B23-B31+B24*Annahmen!$C$5+B25*Annahmen!$C$8+B26*Annahmen!$C$11+B27*Annahmen!$C$19 | C32: =C23-C31+C24*Annahmen!$C$5+C25*Annahmen!$C$8+C26*Annahmen!$C$11+C27*Annahmen!$C$19 | D32: =D23-D31+D24*Annahmen!$C$5+D25*Annahmen!$C$8+D26*Annahmen!$C$11+D27*Annahmen!$C$19 | E32: =E23-E31+E24*Annahmen!$C$5+E25*Annahmen!$C$8+E26*Annahmen!$C$11+E27*Annahmen!$C$19 | F32: =F23-F31+F24*Annahmen!$C$5+F25*Annahmen!$C$8+F26*Annahmen!$C$11+F27*Annahmen!$C$19 | G32: =G23-G31+G24*Annahmen!$C$5+G25*Annahmen!$C$8+G26*Annahmen!$C$11+G27*Annahmen!$C$19
A33: Bruttomarge % | B33: =IF(B28=0,0,B32/B28) | C33: =IF(C28=0,0,C32/C28) | D33: =IF(D28=0,0,D32/D28) | E33: =IF(E28=0,0,E32/E28) | F33: =IF(F28=0,0,F32/F28) | G33: =IF(G28=0,0,G32/G28)
A35: OPERATIVE KOSTEN
A36: Personal | B36: =B9*Annahmen!$C$15 | C36: =C9*Annahmen!$C$15 | D36: =D9*Annahmen!$C$15 | E36: =E9*Annahmen!$C$15 | F36: =F9*Annahmen!$C$15 | G36: =G9*Annahmen!$C$15
A37: Variabler Vertrieb (CAC direkt) | B37: =B5*Annahmen!$C$14 | C37: =C5*Annahmen!$C$14 | D37: =D5*(1-Annahmen!$C$12)*Annahmen!$C$14 | E37: =E5*(1-Annahmen!$C$12)*Annahmen!$C$14 | F37: =F5*(1-Annahmen!$C$12)*Annahmen!$C$14 | G37: =G5*(1-Annahmen!$C$12)*Annahmen!$C$14
A38: Opex gesamt | B38: =B36+B37+B10+B11+B12+B13 | C38: =C36+C37+C10+C11+C12+C13 | D38: =D36+D37+D10+D11+D12+D13 | E38: =E36+E37+E10+E11+E12+E13 | F38: =F36+F37+F10+F11+F12+F13 | G38: =G36+G37+G10+G11+G12+G13
A40: ERGEBNIS & LIQUIDITÄT
A41: EBITDA (inkl. Fördermittel) | B41: =B32-B38+B14 | C41: =C32-C38+C14 | D41: =D32-D38+D14 | E41: =E32-E38+E14 | F41: =F32-F38+F14 | G41: =G32-G38+G14
A42: EBITDA-Marge % | B42: =IF(B28=0,0,B41/B28) | C42: =IF(C28=0,0,C41/C28) | D42: =IF(D28=0,0,D41/D28) | E42: =IF(E28=0,0,E41/E28) | F42: =IF(F28=0,0,F41/F28) | G42: =IF(G28=0,0,G41/G28)
A43: Δ Working Capital | B43: =MAX(0,(B28-0)*Annahmen!$C$16) | C43: =MAX(0,(C28-B28)*Annahmen!$C$16) | D43: =MAX(0,(D28-C28)*Annahmen!$C$16) | E43: =MAX(0,(E28-D28)*Annahmen!$C$16) | F43: =MAX(0,(F28-E28)*Annahmen!$C$16) | G43: =MAX(0,(G28-F28)*Annahmen!$C$16)
A44: Free Cash Flow | B44: =B41-B15-B43 | C44: =C41-C15-C43 | D44: =D41-D15-D43 | E44: =E41-E15-E43 | F44: =F41-F15-F43 | G44: =G41-G15-G43
A45: Kumulierter Cash Flow | B45: =B44 | C45: =B45+C44 | D45: =C45+D44 | E45: =D45+E44 | F45: =E45+F44 | G45: =F45+G44
A47: KENNZAHLEN
...

Sheet Upside
A1: KRONOS Eos — Szenario Upside
A3: Position | B3: 2026 | C3: 2027 | D3: 2028 | E3: 2029 | F3: 2030 | G3: 2031 | H3: Notiz
A4: EINGABEN (gelb = editierbar)
A5: Verkaufte Einheiten | B5: 0 | C5: 18 | D5: 55 | E5: 120 | F5: 220 | G5: 330 | H5: D — Validierungsziel V1/V2
A6: Applikationsprojekte/NRE (Umsatz) | B6: 0 | C6: 400 | D6: 700 | E6: 1100 | F6: 1400 | G6: 1700 | H6: PoC-Studien, Prozessintegration — heutiges KRONOS-Geschäft
A7: Listenpreis blended (k€) | B7: 0 | C7: 52 | D7: 61 | E7: 63 | F7: 64 | G7: 65 | H7: Mix Eos One/Five/Max ≈ 25/55/20 %; 2027 = Pilotpreise
A8: Maschinen-COGS (% v. Liste) | B8: 0 | C8: 0.56 | D8: 0.53 | E8: 0.5 | F8: 0.47 | G8: 0.45 | H8: C — BOM-These, Gate V3
A9: FTE | B9: 9 | C9: 15 | D9: 22 | E9: 30 | F9: 40 | G9: 50
A10: Entwicklung (Sachkosten) | B10: 500 | C10: 650 | D10: 450 | E10: 350 | F10: 350 | G10: 350 | H10: Plattform-Derivat aus Helios-Technik
A11: Zertifizierung (CE/UL) | B11: 0 | C11: 150 | D11: 0 | E11: 0 | F11: 0 | G11: 0
A12: Marketing & Messen | B12: 100 | C12: 400 | D12: 600 | E12: 900 | F12: 1100 | G12: 1300 | H12: LOPEC, productronica, electronica, Formnext
A13: G&A (Sachkosten) | B13: 150 | C13: 350 | D13: 450 | E13: 600 | F13: 700 | G13: 800
A14: Fördermittel (Zufluss) | B14: 250 | C14: 1500 | D14: 1550 | E14: 0 | F14: 0 | G14: 0 | H14: ZIM/Bayern; Upside inkl. EIC 2,5 M€
A15: Capex (inkl. Tooling, Demoflotte) | B15: 200 | C15: 600 | D15: 500 | E15: 550 | F15: 650 | G15: 750
A17: INSTALLIERTE BASIS
A18: Kumulierte Basis (Jahresende) | B18: =B5 | C18: =B18+C5 | D18: =C18+D5 | E18: =D18+E5 | F18: =E18+F5 | G18: =F18+G5
A19: Ø aktive Basis (Jahresmittel) | B19: =(0+B18)/2 | C19: =(B18+C18)/2 | D19: =(C18+D18)/2 | E19: =(D18+E18)/2 | F19: =(E18+F18)/2 | G19: =(F18+G18)/2
A20: Servicefähige Basis (Vorjahresbestand) | B20: =0 | C20: =B18 | D20: =C18 | E20: =D18 | F20: =E18 | G20: =F18
A22: UMSATZ
A23: Maschinenumsatz | B23: =B5*B7 | C23: =C5*C7 | D23: =D5*D7*(1-Annahmen!$D$12*Annahmen!$D$13) | E23: =E5*E7*(1-Annahmen!$D$12*Annahmen!$D$13) | F23: =F5*F7*(1-Annahmen!$D$12*Annahmen!$D$13) | G23: =G5*G7*(1-Annahmen!$D$12*Annahmen!$D$13) | H23: ab 2028 Kanalmix mit Distributorenrabatt
A24: Verbrauchsmaterial | B24: =B19*Annahmen!$D$4 | C24: =C19*Annahmen!$D$4 | D24: =D19*Annahmen!$D$4 | E24: =E19*Annahmen!$D$4 | F24: =F19*Annahmen!$D$4 | G24: =G19*Annahmen!$D$4
A25: Service & Wartung | B25: =B20*Annahmen!$D$6*Annahmen!$D$7*B7 | C25: =C20*Annahmen!$D$6*Annahmen!$D$7*C7 | D25: =D20*Annahmen!$D$6*Annahmen!$D$7*D7 | E25: =E20*Annahmen!$D$6*Annahmen!$D$7*E7 | F25: =F20*Annahmen!$D$6*Annahmen!$D$7*F7 | G25: =G20*Annahmen!$D$6*Annahmen!$D$7*G7
A26: Software (Aion-5X Abo) | B26: =B19*Annahmen!$D$10*Annahmen!$D$9 | C26: =C19*Annahmen!$D$10*Annahmen!$D$9 | D26: =D19*Annahmen!$D$10*Annahmen!$D$9 | E26: =E19*Annahmen!$D$10*Annahmen!$D$9 | F26: =F19*Annahmen!$D$10*Annahmen!$D$9 | G26: =G19*Annahmen!$D$10*Annahmen!$D$9
A27: Applikationsprojekte/NRE | B27: =B6 | C27: =C6 | D27: =D6 | E27: =E6 | F27: =F6 | G27: =G6
A28: Gesamtumsatz | B28: =SUM(B23:B27) | C28: =SUM(C23:C27) | D28: =SUM(D23:D27) | E28: =SUM(E23:E27) | F28: =SUM(F23:F27) | G28: =SUM(G23:G27)
A30: BRUTTOERGEBNIS
A31: COGS Maschinen | B31: =B5*B7*B8 | C31: =C5*C7*C8 | D31: =D5*D7*D8 | E31: =E5*E7*E8 | F31: =F5*F7*F8 | G31: =G5*G7*G8
A32: Bruttoergebnis | B32: =B23-B31+B24*Annahmen!$D$5+B25*Annahmen!$D$8+B26*Annahmen!$D$11+B27*Annahmen!$D$19 | C32: =C23-C31+C24*Annahmen!$D$5+C25*Annahmen!$D$8+C26*Annahmen!$D$11+C27*Annahmen!$D$19 | D32: =D23-D31+D24*Annahmen!$D$5+D25*Annahmen!$D$8+D26*Annahmen!$D$11+D27*Annahmen!$D$19 | E32: =E23-E31+E24*Annahmen!$D$5+E25*Annahmen!$D$8+E26*Annahmen!$D$11+E27*Annahmen!$D$19 | F32: =F23-F31+F24*Annahmen!$D$5+F25*Annahmen!$D$8+F26*Annahmen!$D$11+F27*Annahmen!$D$19 | G32: =G23-G31+G24*Annahmen!$D$5+G25*Annahmen!$D$8+G26*Annahmen!$D$11+G27*Annahmen!$D$19
A33: Bruttomarge % | B33: =IF(B28=0,0,B32/B28) | C33: =IF(C28=0,0,C32/C28) | D33: =IF(D28=0,0,D32/D28) | E33: =IF(E28=0,0,E32/E28) | F33: =IF(F28=0,0,F32/F28) | G33: =IF(G28=0,0,G32/G28)
A35: OPERATIVE KOSTEN
A36: Personal | B36: =B9*Annahmen!$D$15 | C36: =C9*Annahmen!$D$15 | D36: =D9*Annahmen!$D$15 | E36: =E9*Annahmen!$D$15 | F36: =F9*Annahmen!$D$15 | G36: =G9*Annahmen!$D$15
A37: Variabler Vertrieb (CAC direkt) | B37: =B5*Annahmen!$D$14 | C37: =C5*Annahmen!$D$14 | D37: =D5*(1-Annahmen!$D$12)*Annahmen!$D$14 | E37: =E5*(1-Annahmen!$D$12)*Annahmen!$D$14 | F37: =F5*(1-Annahmen!$D$12)*Annahmen!$D$14 | G37: =G5*(1-Annahmen!$D$12)*Annahmen!$D$14
A38: Opex gesamt | B38: =B36+B37+B10+B11+B12+B13 | C38: =C36+C37+C10+C11+C12+C13 | D38: =D36+D37+D10+D11+D12+D13 | E38: =E36+E37+E10+E11+E12+E13 | F38: =F36+F37+F10+F11+F12+F13 | G38: =G36+G37+G10+G11+G12+G13
A40: ERGEBNIS & LIQUIDITÄT
A41: EBITDA (inkl. Fördermittel) | B41: =B32-B38+B14 | C41: =C32-C38+C14 | D41: =D32-D38+D14 | E41: =E32-E38+E14 | F41: =F32-F38+F14 | G41: =G32-G38+G14
A42: EBITDA-Marge % | B42: =IF(B28=0,0,B41/B28) | C42: =IF(C28=0,0,C41/C28) | D42: =IF(D28=0,0,D41/D28) | E42: =IF(E28=0,0,E41/E28) | F42: =IF(F28=0,0,F41/F28) | G42: =IF(G28=0,0,G41/G28)
A43: Δ Working Capital | B43: =MAX(0,(B28-0)*Annahmen!$D$16) | C43: =MAX(0,(C28-B28)*Annahmen!$D$16) | D43: =MAX(0,(D28-C28)*Annahmen!$D$16) | E43: =MAX(0,(E28-D28)*Annahmen!$D$16) | F43: =MAX(0,(F28-E28)*Annahmen!$D$16) | G43: =MAX(0,(G28-F28)*Annahmen!$D$16)
A44: Free Cash Flow | B44: =B41-B15-B43 | C44: =C41-C15-C43 | D44: =D41-D15-D43 | E44: =E41-E15-E43 | F44: =F41-F15-F43 | G44: =G41-G15-G43
A45: Kumulierter Cash Flow | B45: =B44 | C45: =B45+C44 | D45: =C45+D44 | E45: =D45+E44 | F45: =E45+F44 | G45: =F45+G44
A47: KENNZAHLEN
...

Sheet Szenariovergleich
A1: Szenariovergleich — Kernkennzahlen
A3: Kennzahl | B3: Konservativ | C3: Base | D3: Upside
A4: Einheiten Jahr 5 (2031) | B4: =Konservativ!G5 | C4: =Base!G5 | D4: =Upside!G5
A5: Kumulierte installierte Basis 2031 | B5: =Konservativ!G18 | C5: =Base!G18 | D5: =Upside!G18
A6: Umsatz 2031 | B6: =Konservativ!G28 | C6: =Base!G28 | D6: =Upside!G28
A7: — davon wiederkehrend (Material+Service+SW) | B7: =Konservativ!G24+Konservativ!G25+Konservativ!G26 | C7: =Base!G24+Base!G25+Base!G26 | D7: =Upside!G24+Upside!G25+Upside!G26
A8: Bruttomarge 2031 | B8: =Konservativ!G33 | C8: =Base!G33 | D8: =Upside!G33
A9: EBITDA 2031 | B9: =Konservativ!G41 | C9: =Base!G41 | D9: =Upside!G41
A10: EBITDA-Marge 2031 | B10: =Konservativ!G42 | C10: =Base!G42 | D10: =Upside!G42
A11: Kapitalbedarf brutto (inkl. Puffer) | B11: =Konservativ!B48 | C11: =Base!B48 | D11: =Upside!B48
A12: Break-even-Jahr | B12: =Konservativ!B49 | C12: =Base!B49 | D12: =Upside!B49
A14: Datenreihen (für Diagramme)
A15: Jahr | B15: 2026 | C15: 2027 | D15: 2028 | E15: 2029 | F15: 2030 | G15: 2031
A16: Umsatz Konservativ | B16: =Konservativ!B28 | C16: =Konservativ!C28 | D16: =Konservativ!D28 | E16: =Konservativ!E28 | F16: =Konservativ!F28 | G16: =Konservativ!G28
A17: Umsatz Base | B17: =Base!B28 | C17: =Base!C28 | D17: =Base!D28 | E17: =Base!E28 | F17: =Base!F28 | G17: =Base!G28
A18: Umsatz Upside | B18: =Upside!B28 | C18: =Upside!C28 | D18: =Upside!D28 | E18: =Upside!E28 | F18: =Upside!F28 | G18: =Upside!G28
A19: EBITDA Konservativ | B19: =Konservativ!B41 | C19: =Konservativ!C41 | D19: =Konservativ!D41 | E19: =Konservativ!E41 | F19: =Konservativ!F41 | G19: =Konservativ!G41
A20: EBITDA Base | B20: =Base!B41 | C20: =Base!C41 | D20: =Base!D41 | E20: =Base!E41 | F20: =Base!F41 | G20: =Base!G41
A21: EBITDA Upside | B21: =Upside!B41 | C21: =Upside!C41 | D21: =Upside!D41 | E21: =Upside!E41 | F21: =Upside!F41 | G21: =Upside!G41
A22: Kum. Cash Base | B22: =Base!B45 | C22: =Base!C45 | D22: =Base!D45 | E22: =Base!E45 | F22: =Base!F45 | G22: =Base!G45

Sheet Sensitivität
A1: Sensitivitätsanalyse (Base Case)
A2: Wirkung einzelner Treiber auf EBITDA 2031 und Kapitalbedarf. Python-berechnet aus identischer Modelllogik; Formelmodell in den Szenario-Sheets.
A4: Treiber | B4: Variation | C4: EBITDA 2031 (k€) | D4: Δ EBITDA | E4: Kapitalbedarf (k€) | F4: Δ Bedarf
A5: Stückzahlen (-30 %) | B5: -30 % | C5: -786 | D5: -1836 | E5: 16813 | F5: 3639
A6: Stückzahlen (+30 %) | B6: +30 % | C6: 2887 | D6: 1836 | E6: 11184 | F6: -1990
A7: Verkaufspreis (ASP) (-15 %) | B7: -15 % | C7: 137 | D7: -914 | E7: 15124 | F7: 1949
A8: Verkaufspreis (ASP) (+15 %) | B8: +15 % | C8: 1964 | D8: 914 | E8: 11951 | F8: -1224
A9: Maschinen-COGS (+5 pp) | B9: +5 pp | C9: 416 | D9: -635 | E9: 14799 | F9: 1625
A10: Maschinen-COGS (-5 pp) | B10: -5 pp | C10: 1686 | D10: 635 | E10: 12050 | F10: -1124
A11: Attach-Umsätze (-50 %) | B11: -50 % | C11: 141 | D11: -910 | E11: 14882 | F11: 1708
A12: Attach-Umsätze (+50 %) | B12: +50 % | C12: 1960 | D12: 910 | E12: 12182 | F12: -992
A13: CAC (+50 %) | B13: +50 % | C13: 376 | D13: -675 | E13: 14944 | F13: 1770
A14: CAC (-50 %) | B14: -50 % | C14: 1726 | D14: 675 | E14: 11951 | F14: -1223
A15: Basiswert (Base Case) | C15: 1051 | E15: 13174
A17: Tornado: Δ EBITDA 2031 (k€)
A18: Stückzahlen -30 % | B18: -1836
A19: Stückzahlen +30 % | B19: 1836
A20: Verkaufspreis (ASP) -15 % | B20: -914
A21: Verkaufspreis (ASP) +15 % | B21: 914
A22: Attach-Umsätze -50 % | B22: -910
A23: Attach-Umsätze +50 % | B23: 910
A24: CAC +50 % | B24: -675
A25: CAC -50 % | B25: 675
A26: Maschinen-COGS +5 pp | B26: -635
A27: Maschinen-COGS -5 pp | B27: 635
A29: Lesart: Stückzahlen und COGS dominieren; Attach-Umsätze entscheiden über die Margenqualität ab Jahr 4; der Case bricht bei ASP −15 % nicht zusammen (Preissetzungs-Puffer).

Sheet Returns
A1: Investor Returns — Exit-Rechnung
A2: Konvention: Investor stellt den vollen Equity-Bedarf in Tranchen; Anteil = Verhandlungsannahme (Annahmen-Sheet). Terminalperspektive Jahr 7 mit Wachstums-/Margenannahmen je Szenario.
A4: Position | B4: Konservativ | C4: Base | D4: Upside
A5: Investiertes Kapital (= Kapitalbedarf brutto) | B5: =Konservativ!B48 | C5: =Base!B48 | D5: =Upside!B48
A6: Umsatz 2031 (Jahr 5) | B6: =Konservativ!G28 | C6: =Base!G28 | D6: =Upside!G28
A7: Enterprise Value 2031 (Umsatz × Exit-Multiple) | B7: =B6*Annahmen!$B$17 | C7: =C6*Annahmen!$C$17 | D7: =D6*Annahmen!$D$17
A8: MOIC bei Exit Jahr 5 | B8: =B7*Annahmen!$B$18/B5 | C8: =C7*Annahmen!$C$18/C5 | D8: =D7*Annahmen!$D$18/D5
A10: Terminalperspektive Jahr 7 (2033)
A11: Umsatz 2033 (Wachstum p.a.: K 15% / B 30% / U 35%) | B11: =B6*1.3225 | C11: =C6*1.6900 | D11: =D6*1.8225
A12: Enterprise Value 2033 | B12: =B11*Annahmen!$B$17 | C12: =C11*Annahmen!$C$17 | D12: =D11*Annahmen!$D$17
A13: MOIC bei Exit Jahr 7 | B13: =B12*Annahmen!$B$18/B5 | C13: =C12*Annahmen!$C$18/C5 | D13: =D12*Annahmen!$D$18/D5
A14: Cashflows für IRR (t0–t7)
A15: t0 (2026) | B15: =-0.4*B5 | C15: =-0.4*C5 | D15: =-0.4*D5
A16: t1 (2027) | B16: =-0.35*B5 | C16: =-0.35*C5 | D16: =-0.35*D5
A17: t2 (2028) | B17: =-0.25*B5 | C17: =-0.25*C5 | D17: =-0.25*D5
A18: t3 (2029) | B18: =0*B5 | C18: =0*C5 | D18: =0*D5
A19: t4 (2030) | B19: =0*B5 | C19: =0*C5 | D19: =0*D5
A20: t5 (2031) | B20: =0*B5 | C20: =0*C5 | D20: =0*D5
A21: t6 (2032) | B21: =0*B5 | C21: =0*C5 | D21: =0*D5
A22: t7 (2033) | B22: =B12*Annahmen!$B$18 | C22: =C12*Annahmen!$C$18 | D22: =D12*Annahmen!$D$18
A23: IRR (7 Jahre, tranchiert 40/35/25 %) | B23: =IRR(B15:B22) | C23: =IRR(C15:C22) | D23: =IRR(D15:D22)
A25: Lesart: Nur der Upside-Fall liefert venture-taugliche Renditen. Base = solide, aber unter Venture-Schwelle. Konservativ = Kapitalverlust → No-Go-Kriterien in business-plan/investment-thesis.md.
